Traceback (most recent call last):
  File "C:\Users\yoavp\Documents\projects\python_venvs\jupyter-book\lib\site-packages\jupyter_cache\executors\utils.py", line 58, in single_nb_execution
    executenb(
  File "C:\Users\yoavp\Documents\projects\python_venvs\jupyter-book\lib\site-packages\nbclient\client.py", line 1314, in execute
    return NotebookClient(nb=nb, resources=resources, km=km, **kwargs).execute()
  File "C:\Users\yoavp\Documents\projects\python_venvs\jupyter-book\lib\site-packages\jupyter_core\utils\__init__.py", line 165, in wrapped
    return loop.run_until_complete(inner)
  File "C:\Users\yoavp\AppData\Local\Programs\Python\Python310\lib\asyncio\base_events.py", line 649, in run_until_complete
    return future.result()
  File "C:\Users\yoavp\Documents\projects\python_venvs\jupyter-book\lib\site-packages\nbclient\client.py", line 709, in async_execute
    await self.async_execute_cell(
  File "C:\Users\yoavp\Documents\projects\python_venvs\jupyter-book\lib\site-packages\nbclient\client.py", line 1062, in async_execute_cell
    await self._check_raise_for_error(cell, cell_index, exec_reply)
  File "C:\Users\yoavp\Documents\projects\python_venvs\jupyter-book\lib\site-packages\nbclient\client.py", line 918, in _check_raise_for_error
    raise CellExecutionError.from_cell_and_msg(cell, exec_reply_content)
nbclient.exceptions.CellExecutionError: An error occurred while executing the following cell:
------------------
np.roll(data_noise,400)[400-5:400+5]
------------------


[1;31m---------------------------------------------------------------------------[0m
[1;31mNameError[0m                                 Traceback (most recent call last)
Cell [1;32mIn[5], line 1[0m
[1;32m----> 1[0m np[38;5;241m.[39mroll([43mdata_noise[49m,[38;5;241m400[39m)[[38;5;241m400[39m[38;5;241m-[39m[38;5;241m5[39m:[38;5;241m400[39m[38;5;241m+[39m[38;5;241m5[39m]

[1;31mNameError[0m: name 'data_noise' is not defined

