Traceback (most recent call last):
  File "C:\Users\yoavp\Documents\projects\python_venvs\jupyter-book\lib\site-packages\jupyter_cache\executors\utils.py", line 58, in single_nb_execution
    executenb(
  File "C:\Users\yoavp\Documents\projects\python_venvs\jupyter-book\lib\site-packages\nbclient\client.py", line 1314, in execute
    return NotebookClient(nb=nb, resources=resources, km=km, **kwargs).execute()
  File "C:\Users\yoavp\Documents\projects\python_venvs\jupyter-book\lib\site-packages\jupyter_core\utils\__init__.py", line 165, in wrapped
    return loop.run_until_complete(inner)
  File "C:\Users\yoavp\AppData\Local\Programs\Python\Python310\lib\asyncio\base_events.py", line 649, in run_until_complete
    return future.result()
  File "C:\Users\yoavp\Documents\projects\python_venvs\jupyter-book\lib\site-packages\nbclient\client.py", line 709, in async_execute
    await self.async_execute_cell(
  File "C:\Users\yoavp\Documents\projects\python_venvs\jupyter-book\lib\site-packages\nbclient\client.py", line 1062, in async_execute_cell
    await self._check_raise_for_error(cell, cell_index, exec_reply)
  File "C:\Users\yoavp\Documents\projects\python_venvs\jupyter-book\lib\site-packages\nbclient\client.py", line 918, in _check_raise_for_error
    raise CellExecutionError.from_cell_and_msg(cell, exec_reply_content)
nbclient.exceptions.CellExecutionError: An error occurred while executing the following cell:
------------------
K = int(4*fs)
iq_data = data[:K,0] + 1j*data[:K,1]
------------------


[1;31m---------------------------------------------------------------------------[0m
[1;31mIndexError[0m                                Traceback (most recent call last)
Cell [1;32mIn[14], line 2[0m
[0;32m      1[0m K [38;5;241m=[39m [38;5;28mint[39m([38;5;241m4[39m[38;5;241m*[39mfs)
[1;32m----> 2[0m iq_data [38;5;241m=[39m [43mdata[49m[43m[[49m[43m:[49m[43mK[49m[43m,[49m[38;5;241;43m0[39;49m[43m][49m [38;5;241m+[39m [38;5;241m1[39mj[38;5;241m*[39mdata[:K,[38;5;241m1[39m]

[1;31mIndexError[0m: too many indices for array: array is 1-dimensional, but 2 were indexed

